Traceback (most recent call last):
  File "/scratch/pawsey1001/haodongyang/envs/envs/bert/lib/python3.10/site-packages/huggingface_hub/utils/_http.py", line 409, in hf_raise_for_status
    response.raise_for_status()
  File "/scratch/pawsey1001/haodongyang/envs/envs/bert/lib/python3.10/site-packages/requests/models.py", line 1021, in raise_for_status
    raise HTTPError(http_error_msg, response=self)
requests.exceptions.HTTPError: 401 Client Error: Unauthorized for url: https://huggingface.co/microsoft/deberta-small/resolve/main/config.json
The above exception was the direct cause of the following exception:
Traceback (most recent call last):
  File "/scratch/pawsey1001/haodongyang/envs/envs/bert/lib/python3.10/site-packages/transformers/utils/hub.py", line 342, in cached_file
    resolved_file = hf_hub_download(
  File "/scratch/pawsey1001/haodongyang/envs/envs/bert/lib/python3.10/site-packages/huggingface_hub/utils/_validators.py", line 114, in _inner_fn
    return fn(*args, **kwargs)
  File "/scratch/pawsey1001/haodongyang/envs/envs/bert/lib/python3.10/site-packages/huggingface_hub/file_download.py", line 862, in hf_hub_download
    return _hf_hub_download_to_cache_dir(
  File "/scratch/pawsey1001/haodongyang/envs/envs/bert/lib/python3.10/site-packages/huggingface_hub/file_download.py", line 969, in _hf_hub_download_to_cache_dir
    _raise_on_head_call_error(head_call_error, force_download, local_files_only)
  File "/scratch/pawsey1001/haodongyang/envs/envs/bert/lib/python3.10/site-packages/huggingface_hub/file_download.py", line 1486, in _raise_on_head_call_error
    raise head_call_error
  File "/scratch/pawsey1001/haodongyang/envs/envs/bert/lib/python3.10/site-packages/huggingface_hub/file_download.py", line 1376, in _get_metadata_or_catch_error
    metadata = get_hf_file_metadata(
  File "/scratch/pawsey1001/haodongyang/envs/envs/bert/lib/python3.10/site-packages/huggingface_hub/utils/_validators.py", line 114, in _inner_fn
    return fn(*args, **kwargs)
  File "/scratch/pawsey1001/haodongyang/envs/envs/bert/lib/python3.10/site-packages/huggingface_hub/file_download.py", line 1296, in get_hf_file_metadata
    r = _request_wrapper(
  File "/scratch/pawsey1001/haodongyang/envs/envs/bert/lib/python3.10/site-packages/huggingface_hub/file_download.py", line 280, in _request_wrapper
    response = _request_wrapper(
  File "/scratch/pawsey1001/haodongyang/envs/envs/bert/lib/python3.10/site-packages/huggingface_hub/file_download.py", line 304, in _request_wrapper
    hf_raise_for_status(response)
  File "/scratch/pawsey1001/haodongyang/envs/envs/bert/lib/python3.10/site-packages/huggingface_hub/utils/_http.py", line 458, in hf_raise_for_status
    raise _format(RepositoryNotFoundError, message, response) from e
huggingface_hub.errors.RepositoryNotFoundError: 401 Client Error. (Request ID: Root=1-67db0168-3870572c3d1771060ac76465;b85a4d90-3054-4bb2-82d0-cb3cd2c4fba5)
Repository Not Found for url: https://huggingface.co/microsoft/deberta-small/resolve/main/config.json.
Please make sure you specified the correct `repo_id` and `repo_type`.
If you are trying to access a private or gated repo, make sure you are authenticated.
Invalid username or password.
The above exception was the direct cause of the following exception:
Traceback (most recent call last):
  File "/scratch/pawsey1001/haodongyang/loretta/bert_model/run_glue_v5.py", line 414, in <module>
    main()
  File "/scratch/pawsey1001/haodongyang/loretta/bert_model/run_glue_v5.py", line 136, in main
    config = AutoConfig.from_pretrained(
  File "/scratch/pawsey1001/haodongyang/envs/envs/bert/lib/python3.10/site-packages/transformers/models/auto/configuration_auto.py", line 1075, in from_pretrained
    config_dict, unused_kwargs = PretrainedConfig.get_config_dict(pretrained_model_name_or_path, **kwargs)
  File "/scratch/pawsey1001/haodongyang/envs/envs/bert/lib/python3.10/site-packages/transformers/configuration_utils.py", line 594, in get_config_dict
    config_dict, kwargs = cls._get_config_dict(pretrained_model_name_or_path, **kwargs)
  File "/scratch/pawsey1001/haodongyang/envs/envs/bert/lib/python3.10/site-packages/transformers/configuration_utils.py", line 653, in _get_config_dict
    resolved_config_file = cached_file(
  File "/scratch/pawsey1001/haodongyang/envs/envs/bert/lib/python3.10/site-packages/transformers/utils/hub.py", line 365, in cached_file
    raise EnvironmentError(
OSError: microsoft/deberta-small is not a local folder and is not a valid model identifier listed on 'https://huggingface.co/models'
If this is a private repository, make sure to pass a token having permission to this repo either by logging in with `huggingface-cli login` or by passing `token=<your_token>`
Traceback (most recent call last):
  File "/scratch/pawsey1001/haodongyang/envs/envs/bert/lib/python3.10/site-packages/huggingface_hub/utils/_http.py", line 409, in hf_raise_for_status
    response.raise_for_status()
  File "/scratch/pawsey1001/haodongyang/envs/envs/bert/lib/python3.10/site-packages/requests/models.py", line 1021, in raise_for_status
    raise HTTPError(http_error_msg, response=self)
requests.exceptions.HTTPError: 401 Client Error: Unauthorized for url: https://huggingface.co/microsoft/deberta-small/resolve/main/config.json
The above exception was the direct cause of the following exception:
Traceback (most recent call last):
  File "/scratch/pawsey1001/haodongyang/envs/envs/bert/lib/python3.10/site-packages/transformers/utils/hub.py", line 342, in cached_file
    resolved_file = hf_hub_download(
  File "/scratch/pawsey1001/haodongyang/envs/envs/bert/lib/python3.10/site-packages/huggingface_hub/utils/_validators.py", line 114, in _inner_fn
    return fn(*args, **kwargs)
  File "/scratch/pawsey1001/haodongyang/envs/envs/bert/lib/python3.10/site-packages/huggingface_hub/file_download.py", line 862, in hf_hub_download
    return _hf_hub_download_to_cache_dir(
  File "/scratch/pawsey1001/haodongyang/envs/envs/bert/lib/python3.10/site-packages/huggingface_hub/file_download.py", line 969, in _hf_hub_download_to_cache_dir
    _raise_on_head_call_error(head_call_error, force_download, local_files_only)
  File "/scratch/pawsey1001/haodongyang/envs/envs/bert/lib/python3.10/site-packages/huggingface_hub/file_download.py", line 1486, in _raise_on_head_call_error
    raise head_call_error
  File "/scratch/pawsey1001/haodongyang/envs/envs/bert/lib/python3.10/site-packages/huggingface_hub/file_download.py", line 1376, in _get_metadata_or_catch_error
    metadata = get_hf_file_metadata(
  File "/scratch/pawsey1001/haodongyang/envs/envs/bert/lib/python3.10/site-packages/huggingface_hub/utils/_validators.py", line 114, in _inner_fn
    return fn(*args, **kwargs)
  File "/scratch/pawsey1001/haodongyang/envs/envs/bert/lib/python3.10/site-packages/huggingface_hub/file_download.py", line 1296, in get_hf_file_metadata
    r = _request_wrapper(
  File "/scratch/pawsey1001/haodongyang/envs/envs/bert/lib/python3.10/site-packages/huggingface_hub/file_download.py", line 280, in _request_wrapper
    response = _request_wrapper(
  File "/scratch/pawsey1001/haodongyang/envs/envs/bert/lib/python3.10/site-packages/huggingface_hub/file_download.py", line 304, in _request_wrapper
    hf_raise_for_status(response)
  File "/scratch/pawsey1001/haodongyang/envs/envs/bert/lib/python3.10/site-packages/huggingface_hub/utils/_http.py", line 458, in hf_raise_for_status
    raise _format(RepositoryNotFoundError, message, response) from e
huggingface_hub.errors.RepositoryNotFoundError: 401 Client Error. (Request ID: Root=1-67db0168-3870572c3d1771060ac76465;b85a4d90-3054-4bb2-82d0-cb3cd2c4fba5)
Repository Not Found for url: https://huggingface.co/microsoft/deberta-small/resolve/main/config.json.
Please make sure you specified the correct `repo_id` and `repo_type`.
If you are trying to access a private or gated repo, make sure you are authenticated.
Invalid username or password.
The above exception was the direct cause of the following exception:
Traceback (most recent call last):
  File "/scratch/pawsey1001/haodongyang/loretta/bert_model/run_glue_v5.py", line 414, in <module>
    main()
  File "/scratch/pawsey1001/haodongyang/loretta/bert_model/run_glue_v5.py", line 136, in main
    config = AutoConfig.from_pretrained(
  File "/scratch/pawsey1001/haodongyang/envs/envs/bert/lib/python3.10/site-packages/transformers/models/auto/configuration_auto.py", line 1075, in from_pretrained
    config_dict, unused_kwargs = PretrainedConfig.get_config_dict(pretrained_model_name_or_path, **kwargs)
  File "/scratch/pawsey1001/haodongyang/envs/envs/bert/lib/python3.10/site-packages/transformers/configuration_utils.py", line 594, in get_config_dict
    config_dict, kwargs = cls._get_config_dict(pretrained_model_name_or_path, **kwargs)
  File "/scratch/pawsey1001/haodongyang/envs/envs/bert/lib/python3.10/site-packages/transformers/configuration_utils.py", line 653, in _get_config_dict
    resolved_config_file = cached_file(
  File "/scratch/pawsey1001/haodongyang/envs/envs/bert/lib/python3.10/site-packages/transformers/utils/hub.py", line 365, in cached_file
    raise EnvironmentError(
OSError: microsoft/deberta-small is not a local folder and is not a valid model identifier listed on 'https://huggingface.co/models'
If this is a private repository, make sure to pass a token having permission to this repo either by logging in with `huggingface-cli login` or by passing `token=<your_token>`